Workbook

Sheet Dados
A1: DIA 10/04/2024
A2: ID | B2: Ponto do Acidente | C2: Destino | D2: Data | E2: Faixa de Horário | F2: Tempo Base (min) | G2: atend. local (min) | H2: Tempo Hospital (min) | I2: Tempo Total (min) | J2: Nível de Transito | K2: Rota Principal | L2: Alternativa Melhor | M2: Rota Alternativa | N2: Nível de Transito | O2: Ganho (min)
A3: 1 | B3: Ponte Nova | C3: HMC | D3: 46122 | E3: 0.3125 | F3: 7 | G3: 10 | H3: 22 | I3: =F3+G3+H3 -> 39 | J3: Moderado | K3: Av. Miguel Sutil | L3: Não
C4: PSC | D4: 46122 | E4: 0.3125 | F4: 7 | G4: 10 | H4: 26 | I4: =F4+G4+H4 -> 43 | J4: Intenso | K4: R. Barão de Melgaço e R. Joaquim Murtinho | L4: Sim | M4: via Av. Manoel José de Arruda | N4: Moderado | O4: 2
A5: 2 | B5: Santa Isabel | C5: HMC | D5: 46122 | E5: 0.3125 | F5: 1 | G5: 10 | H5: 16 | I5: =F5+G5+H5 -> 27 | J5: Moderado | K5: Av. Miguel Sutil | L5: Não
C6: PSC | D6: 46122 | E6: 0.3125 | F6: 1 | G6: 10 | H6: 28 | I6: =F6+G6+H6 -> 39 | J6: Intenso | K6: Av. Miguel Sutil | L6: Sim | M6: via Rua Traçaia | N6: Moderado | O6: 2
A7: 3 | B7: Santa Rosa | C7: HMC | D7: 46122 | E7: 0.3125 | F7: 9 | G7: 10 | H7: 8 | I7: =F7+G7+H7 -> 27 | J7: Leve | K7: via Av. Miguel Sutil Av. Bernardo Antônio de Oliveira Neto | L7: Não
C8: PSC | D8: 46122 | E8: 0.3125 | F8: 9 | G8: 10 | H8: 20 | I8: =F8+G8+H8 -> 39 | J8: Intenso | K8: Av. Isaac Povoas | L8: Não
A9: 4 | B9: Viaduto da Rodoviaria | C9: HMC | D9: 46122 | E9: 0.3125 | F9: 14 | G9: 10 | H9: 12 | I9: =F9+G9+H9 -> 36 | J9: Leve | K9: Av. Miguel Sutil | L9: Não
C10: PSC | D10: 46122 | E10: 0.3125 | F10: 14 | G10: 10 | H10: 18 | I10: =F10+G10+H10 -> 42 | J10: Intenso | K10: Av. Miguel Sutil | L10: Sim | M10: via Av. Miguel Sutil R. Antônio Batista Belém | N10: Intenso | O10: 2
A11: 5 | B11: Rotatoria com a rua Prof. João Felix | C11: HMC | D11: 46122 | E11: 0.3125 | F11: 22 | G11: 10 | H11: 16 | I11: =F11+G11+H11 -> 48 | J11: Intenso | K11: Av. Miguel Sutil | L11: Não
C12: PSC | D12: 46122 | E12: 0.3125 | F12: 22 | G12: 10 | H12: 12 | I12: =F12+G12+H12 -> 44 | J12: Moderado | K12: Av. Miguel Sutil | L12: Sim | M12: via R. Antônio Batista Belém | N12: Moderado | O12: 2
A14: ID | B14: Ponto do Acidente | C14: Destino | D14: Data | E14: Faixa de Horário | F14: Tempo Base (min) | G14: atend. local (min) | H14: Tempo Hospital (min) | I14: Tempo Total | J14: Nível de Transito | K14: Rota Principal | L14: Alternativa Melhor | M14: Rota Alternativa | N14: Nível de Transito | O14: Ganho (min)
A15: 6 | B15: Ponte Nova | C15: HMC | D15: 46122 | E15: 0.52083333 | F15: 4 | G15: 10 | H15: 18 | I15: =F15+G15+H15 -> 32 | J15: Leve | K15: Av. Miguel Sutil | L15: Não
C16: PSC | D16: 46122 | E16: 0.52083333 | F16: 4 | G16: 10 | H16: 24 | I16: =F16+G16+H16 -> 38 | J16: Moderado | K16: R. Barão de Melgaço e R. Joaquim Murtinho | L16: Sim | M16: via Av. Manoel José de Arruda | N16: Moderado | O16: 4
A17: 7 | B17: Santa Isabel | C17: HMC | D17: 46122 | E17: 0.52083333 | F17: 1 | G17: 10 | H17: 14 | I17: =F17+G17+H17 -> 25 | J17: Moderado | K17: Av. Miguel Sutil | L17: Não
C18: PSC | D18: 46122 | E18: 0.52083333 | F18: 1 | G18: 10 | H18: 30 | I18: =F18+G18+H18 -> 41 | J18: Intenso | K18: Av. Miguel Sutil | L18: Sim | M18: via Rua Traçaia | N18: Moderado | O18: 6
A19: 8 | B19: Santa Rosa | C19: HMC | D19: 46122 | E19: 0.52083333 | F19: 8 | G19: 10 | H19: 8 | I19: =F19+G19+H19 -> 26 | J19: Leve | K19: via Av. Miguel Sutil Av. Bernardo Antônio de Oliveira Neto | L19: Não
C20: PSC | D20: 46122 | E20: 0.52083333 | F20: 8 | G20: 10 | H20: 22 | I20: =F20+G20+H20 -> 40 | J20: Intenso | K20: Av.isaac Povoas | L20: Não
A21: 9 | B21: Viaduto da Rodoviaria | C21: HMC | D21: 46122 | E21: 0.52083333 | F21: 12 | G21: 10 | H21: 10 | I21: =F21+G21+H21 -> 32 | J21: Leve | K21: Av. Miguel Sutil | L21: Não
C22: PSC | D22: 46122 | E22: 0.52083333 | F22: 12 | G22: 10 | H22: 16 | I22: =F22+G22+H22 -> 38 | J22: Intenso | K22: Av. Miguel Sutil | L22: Não
A23: 10 | B23: Rotatoria com a rua Prof. João Felix | C23: HMC | D23: 46122 | E23: 0.52083333 | F23: 18 | G23: 10 | H23: 14 | I23: =F23+G23+H23 -> 42 | J23: Moderado | K23: Av. Miguel Sutil | L23: Não
C24: PSC | D24: 46122 | E24: 0.52083333 | F24: 18 | G24: 10 | H24: 10 | I24: =F24+G24+H24 -> 38 | J24: Moderado | K24: Av. Miguel Sutil | L24: Sim
A26: ID | B26: Ponto do Acidente | C26: Destino | D26: Data | E26: Faixa de Horário | F26: Tempo Base (min) | G26: atend. local (min) | H26: Tempo Hospital (min) | I26: Tempo Total | J26: Nível de Transito | K26: Rota Principal | L26: Alternativa Melhor | M26: Rota Alternativa | N26: Nível de Transito | O26: Ganho (min)
A27: 11 | B27: Ponte Nova | C27: HMC | D27: 46122 | E27: 0.77083333 | F27: 8 | G27: 10 | H27: 18 | I27: =F27+G27+H27 -> 36 | J27: Moderado | K27: Av. Miguel Sutil | L27: Não
C28: PSM | D28: 46122 | E28: 0.77083333 | F28: 8 | G28: 10 | H28: 22 | I28: =F28+G28+H28 -> 40 | J28: Moderado | K28: R. Barão de Melgaço e R. Joaquim Murtinho | L28: Sim | M28: Av. Manoel José de arruda | N28: Moderado | O28: 2
A29: 12 | B29: Santa Isabel | C29: HMC | D29: 46122 | E29: 0.77083333 | F29: 1 | G29: 10 | H29: 14 | I29: =F29+G29+H29 -> 25 | J29: Moderado | K29: Av. Miguel Sutil | L29: Não
C30: PSM | D30: 46122 | E30: 0.77083333 | F30: 1 | G30: 10 | H30: 30 | I30: =F30+G30+H30 -> 41 | J30: Intenso | K30: Av. Miguel Sutil | L30: Sim | M30: Rua Traçaia | N30: Moderado | O30: 6
A31: 13 | B31: Santa Rosa | C31: HMC | D31: 46122 | E31: 0.77083333 | F31: 12 | G31: 10 | H31: 8 | I31: =F31+G31+H31 -> 30 | J31: Leve | K31: via Av. Miguel Sutil Av. Bernardo Antônio de Oliveira Neto | L31: Não
C32: PSC | D32: 46122 | E32: 0.77083333 | F32: 12 | G32: 10 | H32: 20 | I32: =F32+G32+H32 -> 42 | J32: Intenso | K32: Av.isaac Povoas | L32: Não
A33: 14 | B33: Viaduto da Rodoviaria | C33: HMC | D33: 46122 | E33: 0.77083333 | F33: 14 | G33: 10 | H33: 12 | I33: =F33+G33+H33 -> 36 | J33: Moderado | K33: Av. Miguel Sutil | L33: Não
C34: PSC | D34: 46122 | E34: 0.77083333 | F34: 14 | G34: 10 | H34: 14 | I34: =F34+G34+H34 -> 38 | J34: Intenso | K34: Av. Miguel Sutil | L34: Não
A35: 15 | B35: Rotatoria com a rua Prof. João Felix | C35: HMC | D35: 46122 | E35: 0.77083333 | F35: 20 | G35: 10 | H35: 16 | I35: =F35+G35+H35 -> 46 | J35: Intenso | K35: Av. Miguel Sutil | L35: Não
C36: PSC | D36: 46122 | E36: 0.77083333 | F36: 20 | G36: 10 | H36: 9 | I36: =F36+G36+H36 -> 39 | J36: Leve | K36: Av. Miguel Sutil | L36: Não
A39: DIA 09/04/2026
A40: ID | B40: Ponto do Acidente | C40: Destino | D40: Data | E40: Faixa de Horário | F40: Tempo Base (min) | G40: atend. local (min) | H40: Tempo Hospital (min) | I40: Tempo Total (min) | J40: Nível de Transito | K40: Rota Principal | L40: Alternativa Melhor | M40: Rota Alternativa | N40: Nível de Transito | O40: Ganho (min)
A41: 16 | B41: Ponte Nova | C41: HMC | D41: 46121 | E41: 0.3125 | F41: 6 | G41: 10 | H41: 20 | I41: =F41+G41+H41 -> 36 | J41: Moderado | K41: Av. Miguel Sutil | L41: Não
C42: PSC | D42: 46121 | E42: 0.3125 | F42: 6 | G42: 10 | H42: 26 | I42: =F42+G42+H42 -> 42 | J42: Intenso | K42: R. Barão de Melgaço e R. Joaquim Murtinho | L42: Sim | M42: via Av. Manoel José de Arruda | N42: Moderado | O42: 2
A43: 17 | B43: Santa Isabel | C43: HMC | D43: 46121 | E43: 0.3125 | F43: 1 | G43: 10 | H43: 16 | I43: =F43+G43+H43 -> 27 | J43: Moderado | K43: Av. Miguel Sutil | L43: Não
C44: PSC | D44: 46121 | E44: 0.3125 | F44: 1 | G44: 10 | H44: 30 | I44: =F44+G44+H44 -> 41 | J44: Intenso | K44: Av. Miguel Sutil | L44: Sim | M44: via Rua Traçaia | N44: Moderado | O44: 4
...

Sheet Graficos
A1: Data | B1: Horário | C1: Ponto do Acidente | D1: Destino | E1: Tempo Total (min) | F1: Nível de Trânsito
A2: 46122 | B2: 0.3125 | C2: Ponte Nova | D2: HMC | E2: =Dados!$I3 -> 39 | F2: =Dados!$J3 -> Moderado
A3: 46122 | B3: 0.3125 | D3: PSC | E3: =Dados!$I4 -> 43 | F3: =Dados!$J4 -> Intenso
A4: 46122 | B4: 0.3125 | C4: Santa Isabel | D4: HMC | E4: =Dados!$I5 -> 27 | F4: =Dados!$J5 -> Moderado
A5: 46122 | B5: 0.3125 | D5: PSC | E5: =Dados!$I6 -> 39 | F5: =Dados!$J6 -> Intenso
A6: 46122 | B6: 0.3125 | C6: Santa Rosa | D6: HMC | E6: =Dados!$I7 -> 27 | F6: =Dados!$J7 -> Leve
A7: 46122 | B7: 0.3125 | D7: PSC | E7: =Dados!$I8 -> 39 | F7: =Dados!$J8 -> Intenso
A8: 46122 | B8: 0.3125 | C8: Viaduto da Rodoviaria | D8: HMC | E8: =Dados!$I9 -> 36 | F8: =Dados!$J9 -> Leve
A9: 46122 | B9: 0.3125 | D9: PSC | E9: =Dados!$I10 -> 42 | F9: =Dados!$J10 -> Intenso
A10: 46122 | B10: 0.3125 | C10: Rotatoria com a rua Prof. João Felix | D10: HMC | E10: =Dados!$I11 -> 48 | F10: =Dados!$J11 -> Intenso
A11: 46122 | B11: 0.3125 | D11: PSC | E11: =Dados!$I12 -> 44 | F11: =Dados!$J12 -> Moderado
A12: 46122 | B12: 0.52083333 | C12: Ponte Nova | D12: HMC | E12: =Dados!$I15 -> 32 | F12: =Dados!$J15 -> Leve
A13: 46122 | B13: 0.52083333 | D13: PSC | E13: =Dados!$I16 -> 38 | F13: =Dados!$J16 -> Moderado
A14: 46122 | B14: 0.52083333 | C14: Santa Isabel | D14: HMC | E14: =Dados!$I17 -> 25 | F14: =Dados!$J17 -> Moderado
A15: 46122 | B15: 0.52083333 | D15: PSC | E15: =Dados!$I18 -> 41 | F15: =Dados!$J18 -> Intenso
A16: 46122 | B16: 0.52083333 | C16: Santa Rosa | D16: HMC | E16: =Dados!$I19 -> 26 | F16: =Dados!$J19 -> Leve
A17: 46122 | B17: 0.52083333 | D17: PSC | E17: =Dados!$I20 -> 40 | F17: =Dados!$J20 -> Intenso
A18: 46122 | B18: 0.52083333 | C18: Viaduto da Rodoviaria | D18: HMC | E18: =Dados!$I21 -> 32 | F18: =Dados!$J21 -> Leve
A19: 46122 | B19: 0.52083333 | D19: PSC | E19: =Dados!$I22 -> 38 | F19: =Dados!$J22 -> Intenso
A20: 46122 | B20: 0.52083333 | C20: Rotatoria com a rua Prof. João Felix | D20: HMC | E20: =Dados!$I23 -> 42 | F20: =Dados!$J23 -> Moderado
A21: 46122 | B21: 0.52083333 | D21: PSC | E21: =Dados!$I24 -> 38 | F21: =Dados!$J24 -> Moderado
A22: 46122 | B22: 0.77083333 | C22: Ponte Nova | D22: HMC | E22: =Dados!$I27 -> 36 | F22: =Dados!$J27 -> Moderado
A23: 46122 | B23: 0.77083333 | D23: PSC | E23: =Dados!$I28 -> 40 | F23: =Dados!$J28 -> Moderado
A24: 46122 | B24: 0.77083333 | C24: Santa Isabel | D24: HMC | E24: =Dados!$I29 -> 25 | F24: =Dados!$J29 -> Moderado
A25: 46122 | B25: 0.77083333 | D25: PSC | E25: =Dados!$I30 -> 41 | F25: =Dados!$J30 -> Intenso
A26: 46122 | B26: 0.77083333 | C26: Santa Rosa | D26: HMC | E26: =Dados!$I31 -> 30 | F26: =Dados!$J31 -> Leve
A27: 46122 | B27: 0.77083333 | D27: PSC | E27: =Dados!$I32 -> 42 | F27: =Dados!$J32 -> Intenso
A28: 46122 | B28: 0.77083333 | C28: Viaduto da Rodoviaria | D28: HMC | E28: =Dados!$I33 -> 36 | F28: =Dados!$J33 -> Moderado
A29: 46122 | B29: 0.77083333 | D29: PSC | E29: =Dados!$I34 -> 38 | F29: =Dados!$J34 -> Intenso
A30: 46122 | B30: 0.77083333 | C30: Rotatoria com a rua Prof. João Felix | D30: HMC | E30: =Dados!$I35 -> 46 | F30: =Dados!$J35 -> Intenso
A31: 46122 | B31: 0.77083333 | D31: PSC | E31: =Dados!$I36 -> 39 | F31: =Dados!$J36 -> Leve
A32: 46121 | B32: 0.3125 | C32: Ponte Nova | D32: HMC | E32: =Dados!$I41 -> 36 | F32: =Dados!$J41 -> Moderado
A33: 46121 | B33: 0.3125 | D33: PSC | E33: =Dados!$I42 -> 42 | F33: =Dados!$J42 -> Intenso
A34: 46121 | B34: 0.3125 | C34: Santa Isabel | D34: HMC | E34: =Dados!$I43 -> 27 | F34: =Dados!$J43 -> Moderado
A35: 46121 | B35: 0.3125 | D35: PSC | E35: =Dados!$I44 -> 41 | F35: =Dados!$J44 -> Intenso
A36: 46121 | B36: 0.3125 | C36: Santa Rosa | D36: HMC | E36: =Dados!$I45 -> 28 | F36: =Dados!$J45 -> Leve
A37: 46121 | B37: 0.3125 | D37: PSC | E37: =Dados!$I46 -> 42 | F37: =Dados!$J46 -> Intenso
A38: 46121 | B38: 0.3125 | C38: Viaduto da Rodoviaria | D38: HMC | E38: =Dados!$I47 -> 36 | F38: =Dados!$J47 -> Leve
A39: 46121 | B39: 0.3125 | D39: PSC | E39: =Dados!$I48 -> 44 | F39: =Dados!$J48 -> Intenso
A40: 46121 | B40: 0.3125 | C40: Rotatoria com a rua Prof. João Felix | D40: HMC | E40: =Dados!$I49 -> 48 | F40: =Dados!$J49 -> Intenso
...

Sheet Tabela dinâmica 

Sheet Dados1
A1: Data | B1: Horário | C1: Ponto do Acidente | D1: Destino | E1: Tempo Total (min) | F1: Nível de Trânsito
A2: 46122 | B2: 0.3125 | C2: Ponte Nova | D2: HMC | E2: =Dados!$I3 -> 39 | F2: =Dados!$J3 -> Moderado
A3: 46122 | B3: 0.3125 | C3: Ponte Nova | D3: PSC | E3: =Dados!$I4 -> 43 | F3: =Dados!$J4 -> Intenso
A4: 46122 | B4: 0.3125 | C4: Santa Isabel | D4: HMC | E4: =Dados!$I5 -> 27 | F4: =Dados!$J5 -> Moderado
A5: 46122 | B5: 0.3125 | C5: Santa Isabel | D5: PSC | E5: =Dados!$I6 -> 39 | F5: =Dados!$J6 -> Intenso
A6: 46122 | B6: 0.3125 | C6: Santa Rosa | D6: HMC | E6: =Dados!$I7 -> 27 | F6: =Dados!$J7 -> Leve
A7: 46122 | B7: 0.3125 | C7: Santa Rosa | D7: PSC | E7: =Dados!$I8 -> 39 | F7: =Dados!$J8 -> Intenso
A8: 46122 | B8: 0.3125 | C8: Viaduto da Rodoviaria | D8: HMC | E8: =Dados!$I9 -> 36 | F8: =Dados!$J9 -> Leve
A9: 46122 | B9: 0.3125 | C9: Viaduto da Rodoviaria | D9: PSC | E9: =Dados!$I10 -> 42 | F9: =Dados!$J10 -> Intenso
A10: 46122 | B10: 0.3125 | C10: Rotatoria com a rua Prof. João Felix | D10: HMC | E10: =Dados!$I11 -> 48 | F10: =Dados!$J11 -> Intenso
A11: 46122 | B11: 0.3125 | C11: Rotatoria com a rua Prof. João Felix | D11: PSC | E11: =Dados!$I12 -> 44 | F11: =Dados!$J12 -> Moderado
A12: 46122 | B12: 0.52083333 | C12: Ponte Nova | D12: HMC | E12: =Dados!$I15 -> 32 | F12: =Dados!$J15 -> Leve
A13: 46122 | B13: 0.52083333 | C13: Ponte Nova | D13: PSC | E13: =Dados!$I16 -> 38 | F13: =Dados!$J16 -> Moderado
A14: 46122 | B14: 0.52083333 | C14: Santa Isabel | D14: HMC | E14: =Dados!$I17 -> 25 | F14: =Dados!$J17 -> Moderado
A15: 46122 | B15: 0.52083333 | C15: Santa Isabel | D15: PSC | E15: =Dados!$I18 -> 41 | F15: =Dados!$J18 -> Intenso
A16: 46122 | B16: 0.52083333 | C16: Santa Rosa | D16: HMC | E16: =Dados!$I19 -> 26 | F16: =Dados!$J19 -> Leve
A17: 46122 | B17: 0.52083333 | C17: Santa Rosa | D17: PSC | E17: =Dados!$I20 -> 40 | F17: =Dados!$J20 -> Intenso
A18: 46122 | B18: 0.52083333 | C18: Viaduto da Rodoviaria | D18: HMC | E18: =Dados!$I21 -> 32 | F18: =Dados!$J21 -> Leve
A19: 46122 | B19: 0.52083333 | C19: Viaduto da Rodoviaria | D19: PSC | E19: =Dados!$I22 -> 38 | F19: =Dados!$J22 -> Intenso
A20: 46122 | B20: 0.52083333 | C20: Rotatoria com a rua Prof. João Felix | D20: HMC | E20: =Dados!$I23 -> 42 | F20: =Dados!$J23 -> Moderado
A21: 46122 | B21: 0.52083333 | C21: Rotatoria com a rua Prof. João Felix | D21: PSC | E21: =Dados!$I24 -> 38 | F21: =Dados!$J24 -> Moderado
A22: 46122 | B22: 0.77083333 | C22: Ponte Nova | D22: HMC | E22: =Dados!$I27 -> 36 | F22: =Dados!$J27 -> Moderado
A23: 46122 | B23: 0.77083333 | C23: Ponte Nova | D23: PSC | E23: =Dados!$I28 -> 40 | F23: =Dados!$J28 -> Moderado
A24: 46122 | B24: 0.77083333 | C24: Santa Isabel | D24: HMC | E24: =Dados!$I29 -> 25 | F24: =Dados!$J29 -> Moderado
A25: 46122 | B25: 0.77083333 | C25: Santa Isabel | D25: PSC | E25: =Dados!$I30 -> 41 | F25: =Dados!$J30 -> Intenso
A26: 46122 | B26: 0.77083333 | C26: Santa Rosa | D26: HMC | E26: =Dados!$I31 -> 30 | F26: =Dados!$J31 -> Leve
A27: 46122 | B27: 0.77083333 | C27: Santa Rosa | D27: PSC | E27: =Dados!$I32 -> 42 | F27: =Dados!$J32 -> Intenso
A28: 46122 | B28: 0.77083333 | C28: Viaduto da Rodoviaria | D28: HMC | E28: =Dados!$I33 -> 36 | F28: =Dados!$J33 -> Moderado
A29: 46122 | B29: 0.77083333 | C29: Viaduto da Rodoviaria | D29: PSC | E29: =Dados!$I34 -> 38 | F29: =Dados!$J34 -> Intenso
A30: 46122 | B30: 0.77083333 | C30: Rotatoria com a rua Prof. João Felix | D30: HMC | E30: =Dados!$I35 -> 46 | F30: =Dados!$J35 -> Intenso
A31: 46122 | B31: 0.77083333 | C31: Rotatoria com a rua Prof. João Felix | D31: PSC | E31: =Dados!$I36 -> 39 | F31: =Dados!$J36 -> Leve
A32: 46121 | B32: 0.3125 | C32: Ponte Nova | D32: HMC | E32: =Dados!$I41 -> 36 | F32: =Dados!$J41 -> Moderado
A33: 46121 | B33: 0.3125 | C33: Ponte Nova | D33: PSC | E33: =Dados!$I42 -> 42 | F33: =Dados!$J42 -> Intenso
A34: 46121 | B34: 0.3125 | C34: Santa Isabel | D34: HMC | E34: =Dados!$I43 -> 27 | F34: =Dados!$J43 -> Moderado
A35: 46121 | B35: 0.3125 | C35: Santa Isabel | D35: PSC | E35: =Dados!$I44 -> 41 | F35: =Dados!$J44 -> Intenso
A36: 46121 | B36: 0.3125 | C36: Santa Rosa | D36: HMC | E36: =Dados!$I45 -> 28 | F36: =Dados!$J45 -> Leve
A37: 46121 | B37: 0.3125 | C37: Santa Rosa | D37: PSC | E37: =Dados!$I46 -> 42 | F37: =Dados!$J46 -> Intenso
A38: 46121 | B38: 0.3125 | C38: Viaduto da Rodoviaria | D38: HMC | E38: =Dados!$I47 -> 36 | F38: =Dados!$J47 -> Leve
A39: 46121 | B39: 0.3125 | C39: Viaduto da Rodoviaria | D39: PSC | E39: =Dados!$I48 -> 44 | F39: =Dados!$J48 -> Intenso
A40: 46121 | B40: 0.3125 | C40: Rotatoria com a rua Prof. João Felix | D40: HMC | E40: =Dados!$I49 -> 48 | F40: =Dados!$J49 -> Intenso
...

Sheet minimo-maximo
A3: Dia 01 a 10/04/2026 ás 7:30
A4: acidente | B4: hospital | C4: minimo | D4: maximo
A5: Ponte Nova | B5: HMC | C5: =MIN(Dados1!E2,Dados1!E32,Dados1!E62,Dados1!E92,Dados1!E122,Dados1!E152,Dados1!E182,Dados1!E212,Dados1!E242,Dados1!E272) -> 28 | D5: =MAX(Dados1!E2,Dados1!E32,Dados1!E62,Dados1!E92,Dados1!E122,Dados1!E152,Dados1!E182,Dados1!E212,Dados1!E242,Dados1!E272) -> 39
B6: PSC | C6: =MIN(Dados1!E3,Dados1!E33,Dados1!E63,Dados1!E93,Dados1!E123,Dados1!E153,Dados1!E183,Dados1!E213,Dados1!E243,Dados1!E273) -> 32 | D6: =MAX(Dados1!E3,Dados1!E33,Dados1!E63,Dados1!E93,Dados1!E123,Dados1!E153,Dados1!E183,Dados1!E213,Dados1!E243,Dados1!E273) -> 43
A7: Santa Isabel | B7: HMC | C7: =MIN(Dados1!E4,Dados1!E34,Dados1!E64,Dados1!E94,Dados1!E124,Dados1!E154,Dados1!E184,Dados1!E214,Dados1!E244,Dados1!E274) -> 21 | D7: =MAX(Dados1!E4,Dados1!E34,Dados1!E64,Dados1!E94,Dados1!E124,Dados1!E154,Dados1!E184,Dados1!E214,Dados1!E244,Dados1!E274) -> 31
B8: PSC | C8: =MIN(Dados1!E5,Dados1!E35,Dados1!E65,Dados1!E95,Dados1!E125,Dados1!E155,Dados1!E185,Dados1!E215,Dados1!E245,Dados1!E275) -> 29 | D8: =MAX(Dados1!E5,Dados1!E35,Dados1!E65,Dados1!E95,Dados1!E125,Dados1!E155,Dados1!E185,Dados1!E215,Dados1!E245,Dados1!E275) -> 41
A9: Santa Rosa | B9: HMC | C9: =MIN(Dados1!E6,Dados1!E36,Dados1!E66,Dados1!E96,Dados1!E126,Dados1!E156,Dados1!E186,Dados1!E216,Dados1!E246,Dados1!E276) -> 21 | D9: =MAX(Dados1!E6,Dados1!E36,Dados1!E66,Dados1!E96,Dados1!E126,Dados1!E156,Dados1!E186,Dados1!E216,Dados1!E246,Dados1!E276) -> 30
B10: PSC | C10: =MIN(Dados1!E7,Dados1!E37,Dados1!E67,Dados1!E97,Dados1!E127,Dados1!E157,Dados1!E187,Dados1!E217,Dados1!E247,Dados1!E277) -> 28 | D10: =MAX(Dados1!E7,Dados1!E37,Dados1!E67,Dados1!E97,Dados1!E127,Dados1!E157,Dados1!E187,Dados1!E217,Dados1!E247,Dados1!E277) -> 42
A11: Viaduto da Rodoviaria | B11: HMC | C11: =MIN(Dados1!E8,Dados1!E38,Dados1!E68,Dados1!E98,Dados1!E128,Dados1!E158,Dados1!E188,Dados1!E218,Dados1!E248,Dados1!E278) -> 27 | D11: =MAX(Dados1!E8,Dados1!E38,Dados1!E68,Dados1!E98,Dados1!E128,Dados1!E158,Dados1!E188,Dados1!E218,Dados1!E248,Dados1!E278) -> 36
B12: PSC | C12: =MIN(Dados1!E9,Dados1!E39,Dados1!E69,Dados1!E99,Dados1!E129,Dados1!E159,Dados1!E189,Dados1!E219,Dados1!E249,Dados1!E279) -> 28 | D12: =MAX(Dados1!E9,Dados1!E39,Dados1!E69,Dados1!E99,Dados1!E129,Dados1!E159,Dados1!E189,Dados1!E219,Dados1!E249,Dados1!E279) -> 44
A13: Rotatoria com a rua Prof. João Felix | B13: HMC | C13: =MIN(Dados1!E10,Dados1!E40,Dados1!E70,Dados1!E100,Dados1!E130,Dados1!E160,Dados1!E190,Dados1!E220,Dados1!E250,Dados1!E280) -> 31 | D13: =MAX(Dados1!E10,Dados1!E40,Dados1!E70,Dados1!E100,Dados1!E130,Dados1!E160,Dados1!E190,Dados1!E220,Dados1!E250,Dados1!E280) -> 48
B14: PSC | C14: =MIN(Dados1!E11,Dados1!E41,Dados1!E71,Dados1!E101,Dados1!E131,Dados1!E161,Dados1!E191,Dados1!E221,Dados1!E251,Dados1!E281) -> 29 | D14: =MAX(Dados1!E11,Dados1!E41,Dados1!E71,Dados1!E101,Dados1!E131,Dados1!E161,Dados1!E191,Dados1!E221,Dados1!E251,Dados1!E281) -> 44
A32: Dia 01 a 10/04/2026 ás 12:30
A33: acidente | B33: hospital | C33: minimo | D33: maximo
A34: Ponte Nova | B34: HMC | C34: =MIN(Dados1!E12,Dados1!E42,Dados1!E72,Dados1!E102,Dados1!E132,Dados1!E162,Dados1!E192,Dados1!E222,Dados1!E252,Dados1!E282) -> 28 | D34: =MAX(Dados1!E12,Dados1!E42,Dados1!E72,Dados1!E102,Dados1!E132,Dados1!E162,Dados1!E192,Dados1!E222,Dados1!E252,Dados1!E282) -> 32
B35: PSC | C35: =MIN(Dados1!E13,Dados1!E43,Dados1!E73,Dados1!E103,Dados1!E133,Dados1!E163,Dados1!E193,Dados1!E223,Dados1!E253,Dados1!E283) -> 32 | D35: =MAX(Dados1!E13,Dados1!E43,Dados1!E73,Dados1!E103,Dados1!E133,Dados1!E163,Dados1!E193,Dados1!E223,Dados1!E253,Dados1!E283) -> 40
A36: Santa Isabel | B36: HMC | C36: =MIN(Dados1!E14,Dados1!E44,Dados1!E74,Dados1!E104,Dados1!E134,Dados1!E164,Dados1!E194,Dados1!E224,Dados1!E254,Dados1!E284) -> 21 | D36: =MAX(Dados1!E14,Dados1!E44,Dados1!E74,Dados1!E104,Dados1!E134,Dados1!E164,Dados1!E194,Dados1!E224,Dados1!E254,Dados1!E284) -> 25
B37: PSC | C37: =MIN(Dados1!E15,Dados1!E45,Dados1!E75,Dados1!E105,Dados1!E135,Dados1!E165,Dados1!E195,Dados1!E225,Dados1!E255,Dados1!E285) -> 29 | D37: =MAX(Dados1!E15,Dados1!E45,Dados1!E75,Dados1!E105,Dados1!E135,Dados1!E165,Dados1!E195,Dados1!E225,Dados1!E255,Dados1!E285) -> 41
A38: Santa Rosa | B38: HMC | C38: =MIN(Dados1!E16,Dados1!E46,Dados1!E76,Dados1!E106,Dados1!E136,Dados1!E166,Dados1!E196,Dados1!E226,Dados1!E256,Dados1!E286) -> 21 | D38: =MAX(Dados1!E16,Dados1!E46,Dados1!E76,Dados1!E106,Dados1!E136,Dados1!E166,Dados1!E196,Dados1!E226,Dados1!E256,Dados1!E286) -> 26
B39: PSC | C39: =MIN(Dados1!E17,Dados1!E47,Dados1!E77,Dados1!E107,Dados1!E137,Dados1!E167,Dados1!E197,Dados1!E227,Dados1!E257,Dados1!E287) -> 28 | D39: =MAX(Dados1!E17,Dados1!E47,Dados1!E77,Dados1!E107,Dados1!E137,Dados1!E167,Dados1!E197,Dados1!E227,Dados1!E257,Dados1!E287) -> 40
A40: Viaduto da Rodoviaria | B40: HMC | C40: =MIN(Dados1!E18,Dados1!E48,Dados1!E78,Dados1!E108,Dados1!E138,Dados1!E168,Dados1!E198,Dados1!E228,Dados1!E258,Dados1!E288) -> 27 | D40: =MAX(Dados1!E18,Dados1!E48,Dados1!E78,Dados1!E108,Dados1!E138,Dados1!E168,Dados1!E198,Dados1!E228,Dados1!E258,Dados1!E288) -> 32
B41: PSC | C41: =MIN(Dados1!E19,Dados1!E49,Dados1!E79,Dados1!E109,Dados1!E139,Dados1!E169,Dados1!E199,Dados1!E229,Dados1!E259,Dados1!E289) -> 29 | D41: =MAX(Dados1!E19,Dados1!E49,Dados1!E79,Dados1!E109,Dados1!E139,Dados1!E169,Dados1!E199,Dados1!E229,Dados1!E259,Dados1!E289) -> 38
A42: Rotatoria com a rua Prof. João Felix | B42: HMC | C42: =MIN(Dados1!E20,Dados1!E50,Dados1!E80,Dados1!E110,Dados1!E140,Dados1!E170,Dados1!E200,Dados1!E230,Dados1!E260,Dados1!E290) -> 31 | D42: =MAX(Dados1!E20,Dados1!E50,Dados1!E80,Dados1!E110,Dados1!E140,Dados1!E170,Dados1!E200,Dados1!E230,Dados1!E260,Dados1!E290) -> 42
B43: PSC | C43: =MIN(Dados1!E21,Dados1!E51,Dados1!E81,Dados1!E111,Dados1!E141,Dados1!E171,Dados1!E201,Dados1!E231,Dados1!E261,Dados1!E291) -> 30 | D43: =MAX(Dados1!E21,Dados1!E51,Dados1!E81,Dados1!E111,Dados1!E141,Dados1!E171,Dados1!E201,Dados1!E231,Dados1!E261,Dados1!E291) -> 45
A58: Dia 01 a 10/04/2026 ás 18:30
A59: acidente | B59: hospital | C59: minimo | D59: maximo
A60: Ponte Nova | B60: HMC | C60: =MIN(Dados1!E22,Dados1!E52,Dados1!E82,Dados1!E112,Dados1!E142,Dados1!E172,Dados1!E202,Dados1!E232,Dados1!E262,Dados1!E292) -> 30 | D60: =MAX(Dados1!E22,Dados1!E52,Dados1!E82,Dados1!E112,Dados1!E142,Dados1!E172,Dados1!E202,Dados1!E232,Dados1!E262,Dados1!E292) -> 36
B61: PSC | C61: =MIN(Dados1!E23,Dados1!E53,Dados1!E83,Dados1!E113,Dados1!E143,Dados1!E173,Dados1!E203,Dados1!E233,Dados1!E263,Dados1!E293) -> 32 | D61: =MAX(Dados1!E23,Dados1!E53,Dados1!E83,Dados1!E113,Dados1!E143,Dados1!E173,Dados1!E203,Dados1!E233,Dados1!E263,Dados1!E293) -> 40
A62: Santa Isabel | B62: HMC | C62: =MIN(Dados1!E24,Dados1!E54,Dados1!E84,Dados1!E114,Dados1!E144,Dados1!E174,Dados1!E204,Dados1!E234,Dados1!E264,Dados1!E294) -> 23 | D62: =MAX(Dados1!E24,Dados1!E54,Dados1!E84,Dados1!E114,Dados1!E144,Dados1!E174,Dados1!E204,Dados1!E234,Dados1!E264,Dados1!E294) -> 25
B63: PSC | C63: =MIN(Dados1!E25,Dados1!E55,Dados1!E85,Dados1!E115,Dados1!E145,Dados1!E175,Dados1!E205,Dados1!E235,Dados1!E265,Dados1!E295) -> 31 | D63: =MAX(Dados1!E25,Dados1!E55,Dados1!E85,Dados1!E115,Dados1!E145,Dados1!E175,Dados1!E205,Dados1!E235,Dados1!E265,Dados1!E295) -> 41
A64: Santa Rosa | B64: HMC | C64: =MIN(Dados1!E26,Dados1!E56,Dados1!E86,Dados1!E116,Dados1!E146,Dados1!E176,Dados1!E206,Dados1!E236,Dados1!E266,Dados1!E296) -> 21 | D64: =MAX(Dados1!E26,Dados1!E56,Dados1!E86,Dados1!E116,Dados1!E146,Dados1!E176,Dados1!E206,Dados1!E236,Dados1!E266,Dados1!E296) -> 30
B65: PSC | C65: =MIN(Dados1!E27,Dados1!E57,Dados1!E87,Dados1!E117,Dados1!E147,Dados1!E177,Dados1!E207,Dados1!E237,Dados1!E267,Dados1!E297) -> 30 | D65: =MAX(Dados1!E27,Dados1!E57,Dados1!E87,Dados1!E117,Dados1!E147,Dados1!E177,Dados1!E207,Dados1!E237,Dados1!E267,Dados1!E297) -> 42
A66: Viaduto da Rodoviaria | B66: HMC | C66: =MIN(Dados1!E28,Dados1!E58,Dados1!E88,Dados1!E118,Dados1!E148,Dados1!E178,Dados1!E208,Dados1!E238,Dados1!E268,Dados1!E298) -> 29 | D66: =MAX(Dados1!E28,Dados1!E58,Dados1!E88,Dados1!E118,Dados1!E148,Dados1!E178,Dados1!E208,Dados1!E238,Dados1!E268,Dados1!E298) -> 38
B67: PSC | C67: =MIN(Dados1!E29,Dados1!E59,Dados1!E89,Dados1!E119,Dados1!E149,Dados1!E179,Dados1!E209,Dados1!E239,Dados1!E269,Dados1!E299) -> 32 | D67: =MAX(Dados1!E29,Dados1!E59,Dados1!E89,Dados1!E119,Dados1!E149,Dados1!E179,Dados1!E209,Dados1!E239,Dados1!E269,Dados1!E299) -> 40
A68: Rotatoria com a rua Prof. João Felix | B68: HMC | C68: =MIN(Dados1!E30,Dados1!E60,Dados1!E90,Dados1!E120,Dados1!E150,Dados1!E180,Dados1!E210,Dados1!E240,Dados1!E270,Dados1!E300) -> 36 | D68: =MAX(Dados1!E30,Dados1!E60,Dados1!E90,Dados1!E120,Dados1!E150,Dados1!E180,Dados1!E210,Dados1!E240,Dados1!E270,Dados1!E300) -> 46
B69: PSC | C69: =MIN(Dados1!E31,Dados1!E61,Dados1!E91,Dados1!E121,Dados1!E151,Dados1!E181,Dados1!E211,Dados1!E241,Dados1!E271,Dados1!E30) -> 32 | D69: =MAX(Dados1!E31,Dados1!E61,Dados1!E91,Dados1!E121,Dados1!E151,Dados1!E181,Dados1!E211,Dados1!E241,Dados1!E271,Dados1!E30) -> 46

Sheet Cópia de minimo-maximo
A3: Dia 01 a 10/04/2026 ás 7:30
A4: acidente | B4: hospital | C4: minimo | D4: maximo
A5: Ponte Nova | B5: HMC | C5: =MIN(Dados1!E2,Dados1!E32,Dados1!E62,Dados1!E92,Dados1!E122,Dados1!E152,Dados1!E182,Dados1!E212,Dados1!E242,Dados1!E272) -> 28 | D5: =MAX(Dados1!E2,Dados1!E32,Dados1!E62,Dados1!E92,Dados1!E122,Dados1!E152,Dados1!E182,Dados1!E212,Dados1!E242,Dados1!E272) -> 39
B6: PSC | C6: =MIN(Dados1!E3,Dados1!E33,Dados1!E63,Dados1!E93,Dados1!E123,Dados1!E153,Dados1!E183,Dados1!E213,Dados1!E243,Dados1!E273) -> 32 | D6: =MAX(Dados1!E3,Dados1!E33,Dados1!E63,Dados1!E93,Dados1!E123,Dados1!E153,Dados1!E183,Dados1!E213,Dados1!E243,Dados1!E273) -> 43
A7: Santa Isabel | B7: HMC | C7: =MIN(Dados1!E4,Dados1!E34,Dados1!E64,Dados1!E94,Dados1!E124,Dados1!E154,Dados1!E184,Dados1!E214,Dados1!E244,Dados1!E274) -> 21 | D7: =MAX(Dados1!E4,Dados1!E34,Dados1!E64,Dados1!E94,Dados1!E124,Dados1!E154,Dados1!E184,Dados1!E214,Dados1!E244,Dados1!E274) -> 31
B8: PSC | C8: =MIN(Dados1!E5,Dados1!E35,Dados1!E65,Dados1!E95,Dados1!E125,Dados1!E155,Dados1!E185,Dados1!E215,Dados1!E245,Dados1!E275) -> 29 | D8: =MAX(Dados1!E5,Dados1!E35,Dados1!E65,Dados1!E95,Dados1!E125,Dados1!E155,Dados1!E185,Dados1!E215,Dados1!E245,Dados1!E275) -> 41
A9: Santa Rosa | B9: HMC | C9: =MIN(Dados1!E6,Dados1!E36,Dados1!E66,Dados1!E96,Dados1!E126,Dados1!E156,Dados1!E186,Dados1!E216,Dados1!E246,Dados1!E276) -> 21 | D9: =MAX(Dados1!E6,Dados1!E36,Dados1!E66,Dados1!E96,Dados1!E126,Dados1!E156,Dados1!E186,Dados1!E216,Dados1!E246,Dados1!E276) -> 30
B10: PSC | C10: =MIN(Dados1!E7,Dados1!E37,Dados1!E67,Dados1!E97,Dados1!E127,Dados1!E157,Dados1!E187,Dados1!E217,Dados1!E247,Dados1!E277) -> 28 | D10: =MAX(Dados1!E7,Dados1!E37,Dados1!E67,Dados1!E97,Dados1!E127,Dados1!E157,Dados1!E187,Dados1!E217,Dados1!E247,Dados1!E277) -> 42
A11: Viaduto da Rodoviaria | B11: HMC | C11: =MIN(Dados1!E8,Dados1!E38,Dados1!E68,Dados1!E98,Dados1!E128,Dados1!E158,Dados1!E188,Dados1!E218,Dados1!E248,Dados1!E278) -> 27 | D11: =MAX(Dados1!E8,Dados1!E38,Dados1!E68,Dados1!E98,Dados1!E128,Dados1!E158,Dados1!E188,Dados1!E218,Dados1!E248,Dados1!E278) -> 36
B12: PSC | C12: =MIN(Dados1!E9,Dados1!E39,Dados1!E69,Dados1!E99,Dados1!E129,Dados1!E159,Dados1!E189,Dados1!E219,Dados1!E249,Dados1!E279) -> 28 | D12: =MAX(Dados1!E9,Dados1!E39,Dados1!E69,Dados1!E99,Dados1!E129,Dados1!E159,Dados1!E189,Dados1!E219,Dados1!E249,Dados1!E279) -> 44
A13: Rotatoria com a rua Prof. João Felix | B13: HMC | C13: =MIN(Dados1!E10,Dados1!E40,Dados1!E70,Dados1!E100,Dados1!E130,Dados1!E160,Dados1!E190,Dados1!E220,Dados1!E250,Dados1!E280) -> 31 | D13: =MAX(Dados1!E10,Dados1!E40,Dados1!E70,Dados1!E100,Dados1!E130,Dados1!E160,Dados1!E190,Dados1!E220,Dados1!E250,Dados1!E280) -> 48
B14: PSC | C14: =MIN(Dados1!E11,Dados1!E41,Dados1!E71,Dados1!E101,Dados1!E131,Dados1!E161,Dados1!E191,Dados1!E221,Dados1!E251,Dados1!E281) -> 29 | D14: =MAX(Dados1!E11,Dados1!E41,Dados1!E71,Dados1!E101,Dados1!E131,Dados1!E161,Dados1!E191,Dados1!E221,Dados1!E251,Dados1!E281) -> 44
A32: Dia 01 a 10/04/2026 ás 12:30
A33: acidente | B33: hospital | C33: minimo | D33: maximo
A34: Ponte Nova | B34: HMC | C34: =MIN(Dados1!E12,Dados1!E42,Dados1!E72,Dados1!E102,Dados1!E132,Dados1!E162,Dados1!E192,Dados1!E222,Dados1!E252,Dados1!E282) -> 28 | D34: =MAX(Dados1!E12,Dados1!E42,Dados1!E72,Dados1!E102,Dados1!E132,Dados1!E162,Dados1!E192,Dados1!E222,Dados1!E252,Dados1!E282) -> 32
B35: PSC | C35: =MIN(Dados1!E13,Dados1!E43,Dados1!E73,Dados1!E103,Dados1!E133,Dados1!E163,Dados1!E193,Dados1!E223,Dados1!E253,Dados1!E283) -> 32 | D35: =MAX(Dados1!E13,Dados1!E43,Dados1!E73,Dados1!E103,Dados1!E133,Dados1!E163,Dados1!E193,Dados1!E223,Dados1!E253,Dados1!E283) -> 40
A36: Santa Isabel | B36: HMC | C36: =MIN(Dados1!E14,Dados1!E44,Dados1!E74,Dados1!E104,Dados1!E134,Dados1!E164,Dados1!E194,Dados1!E224,Dados1!E254,Dados1!E284) -> 21 | D36: =MAX(Dados1!E14,Dados1!E44,Dados1!E74,Dados1!E104,Dados1!E134,Dados1!E164,Dados1!E194,Dados1!E224,Dados1!E254,Dados1!E284) -> 25
B37: PSC | C37: =MIN(Dados1!E15,Dados1!E45,Dados1!E75,Dados1!E105,Dados1!E135,Dados1!E165,Dados1!E195,Dados1!E225,Dados1!E255,Dados1!E285) -> 29 | D37: =MAX(Dados1!E15,Dados1!E45,Dados1!E75,Dados1!E105,Dados1!E135,Dados1!E165,Dados1!E195,Dados1!E225,Dados1!E255,Dados1!E285) -> 41
A38: Santa Rosa | B38: HMC | C38: =MIN(Dados1!E16,Dados1!E46,Dados1!E76,Dados1!E106,Dados1!E136,Dados1!E166,Dados1!E196,Dados1!E226,Dados1!E256,Dados1!E286) -> 21 | D38: =MAX(Dados1!E16,Dados1!E46,Dados1!E76,Dados1!E106,Dados1!E136,Dados1!E166,Dados1!E196,Dados1!E226,Dados1!E256,Dados1!E286) -> 26
B39: PSC | C39: =MIN(Dados1!E17,Dados1!E47,Dados1!E77,Dados1!E107,Dados1!E137,Dados1!E167,Dados1!E197,Dados1!E227,Dados1!E257,Dados1!E287) -> 28 | D39: =MAX(Dados1!E17,Dados1!E47,Dados1!E77,Dados1!E107,Dados1!E137,Dados1!E167,Dados1!E197,Dados1!E227,Dados1!E257,Dados1!E287) -> 40
A40: Viaduto da Rodoviaria | B40: HMC | C40: =MIN(Dados1!E18,Dados1!E48,Dados1!E78,Dados1!E108,Dados1!E138,Dados1!E168,Dados1!E198,Dados1!E228,Dados1!E258,Dados1!E288) -> 27 | D40: =MAX(Dados1!E18,Dados1!E48,Dados1!E78,Dados1!E108,Dados1!E138,Dados1!E168,Dados1!E198,Dados1!E228,Dados1!E258,Dados1!E288) -> 32
B41: PSC | C41: =MIN(Dados1!E19,Dados1!E49,Dados1!E79,Dados1!E109,Dados1!E139,Dados1!E169,Dados1!E199,Dados1!E229,Dados1!E259,Dados1!E289) -> 29 | D41: =MAX(Dados1!E19,Dados1!E49,Dados1!E79,Dados1!E109,Dados1!E139,Dados1!E169,Dados1!E199,Dados1!E229,Dados1!E259,Dados1!E289) -> 38
A42: Rotatoria com a rua Prof. João Felix | B42: HMC | C42: =MIN(Dados1!E20,Dados1!E50,Dados1!E80,Dados1!E110,Dados1!E140,Dados1!E170,Dados1!E200,Dados1!E230,Dados1!E260,Dados1!E290) -> 31 | D42: =MAX(Dados1!E20,Dados1!E50,Dados1!E80,Dados1!E110,Dados1!E140,Dados1!E170,Dados1!E200,Dados1!E230,Dados1!E260,Dados1!E290) -> 42
B43: PSC | C43: =MIN(Dados1!E21,Dados1!E51,Dados1!E81,Dados1!E111,Dados1!E141,Dados1!E171,Dados1!E201,Dados1!E231,Dados1!E261,Dados1!E291) -> 30 | D43: =MAX(Dados1!E21,Dados1!E51,Dados1!E81,Dados1!E111,Dados1!E141,Dados1!E171,Dados1!E201,Dados1!E231,Dados1!E261,Dados1!E291) -> 45
A58: Dia 01 a 10/04/2026 ás 18:30
A59: acidente | B59: hospital | C59: minimo | D59: maximo
A60: Ponte Nova | B60: HMC | C60: =MIN(Dados1!E22,Dados1!E52,Dados1!E82,Dados1!E112,Dados1!E142,Dados1!E172,Dados1!E202,Dados1!E232,Dados1!E262,Dados1!E292) -> 30 | D60: =MAX(Dados1!E22,Dados1!E52,Dados1!E82,Dados1!E112,Dados1!E142,Dados1!E172,Dados1!E202,Dados1!E232,Dados1!E262,Dados1!E292) -> 36
B61: PSC | C61: =MIN(Dados1!E23,Dados1!E53,Dados1!E83,Dados1!E113,Dados1!E143,Dados1!E173,Dados1!E203,Dados1!E233,Dados1!E263,Dados1!E293) -> 32 | D61: =MAX(Dados1!E23,Dados1!E53,Dados1!E83,Dados1!E113,Dados1!E143,Dados1!E173,Dados1!E203,Dados1!E233,Dados1!E263,Dados1!E293) -> 40
A62: Santa Isabel | B62: HMC | C62: =MIN(Dados1!E24,Dados1!E54,Dados1!E84,Dados1!E114,Dados1!E144,Dados1!E174,Dados1!E204,Dados1!E234,Dados1!E264,Dados1!E294) -> 23 | D62: =MAX(Dados1!E24,Dados1!E54,Dados1!E84,Dados1!E114,Dados1!E144,Dados1!E174,Dados1!E204,Dados1!E234,Dados1!E264,Dados1!E294) -> 25
B63: PSC | C63: =MIN(Dados1!E25,Dados1!E55,Dados1!E85,Dados1!E115,Dados1!E145,Dados1!E175,Dados1!E205,Dados1!E235,Dados1!E265,Dados1!E295) -> 31 | D63: =MAX(Dados1!E25,Dados1!E55,Dados1!E85,Dados1!E115,Dados1!E145,Dados1!E175,Dados1!E205,Dados1!E235,Dados1!E265,Dados1!E295) -> 41
A64: Santa Rosa | B64: HMC | C64: =MIN(Dados1!E26,Dados1!E56,Dados1!E86,Dados1!E116,Dados1!E146,Dados1!E176,Dados1!E206,Dados1!E236,Dados1!E266,Dados1!E296) -> 21 | D64: =MAX(Dados1!E26,Dados1!E56,Dados1!E86,Dados1!E116,Dados1!E146,Dados1!E176,Dados1!E206,Dados1!E236,Dados1!E266,Dados1!E296) -> 30
B65: PSC | C65: =MIN(Dados1!E27,Dados1!E57,Dados1!E87,Dados1!E117,Dados1!E147,Dados1!E177,Dados1!E207,Dados1!E237,Dados1!E267,Dados1!E297) -> 30 | D65: =MAX(Dados1!E27,Dados1!E57,Dados1!E87,Dados1!E117,Dados1!E147,Dados1!E177,Dados1!E207,Dados1!E237,Dados1!E267,Dados1!E297) -> 42
A66: Viaduto da Rodoviaria | B66: HMC | C66: =MIN(Dados1!E28,Dados1!E58,Dados1!E88,Dados1!E118,Dados1!E148,Dados1!E178,Dados1!E208,Dados1!E238,Dados1!E268,Dados1!E298) -> 29 | D66: =MAX(Dados1!E28,Dados1!E58,Dados1!E88,Dados1!E118,Dados1!E148,Dados1!E178,Dados1!E208,Dados1!E238,Dados1!E268,Dados1!E298) -> 38
B67: PSC | C67: =MIN(Dados1!E29,Dados1!E59,Dados1!E89,Dados1!E119,Dados1!E149,Dados1!E179,Dados1!E209,Dados1!E239,Dados1!E269,Dados1!E299) -> 32 | D67: =MAX(Dados1!E29,Dados1!E59,Dados1!E89,Dados1!E119,Dados1!E149,Dados1!E179,Dados1!E209,Dados1!E239,Dados1!E269,Dados1!E299) -> 40
A68: Rotatoria com a rua Prof. João Felix | B68: HMC | C68: =MIN(Dados1!E30,Dados1!E60,Dados1!E90,Dados1!E120,Dados1!E150,Dados1!E180,Dados1!E210,Dados1!E240,Dados1!E270,Dados1!E300) -> 36 | D68: =MAX(Dados1!E30,Dados1!E60,Dados1!E90,Dados1!E120,Dados1!E150,Dados1!E180,Dados1!E210,Dados1!E240,Dados1!E270,Dados1!E300) -> 46
B69: PSC | C69: =MIN(Dados1!E31,Dados1!E61,Dados1!E91,Dados1!E121,Dados1!E151,Dados1!E181,Dados1!E211,Dados1!E241,Dados1!E271,Dados1!E30) -> 32 | D69: =MAX(Dados1!E31,Dados1!E61,Dados1!E91,Dados1!E121,Dados1!E151,Dados1!E181,Dados1!E211,Dados1!E241,Dados1!E271,Dados1!E30) -> 46
